Workbook

Sheet Cover
B3: 46174
B4: Carlos Arizcuren Elizondo
B7: Table of Contents
B8: Drivers and Assumptions
B9: 3-Statement Financial Analysis
B10: Debt scheudle chart
B11: Weighted Average Cost of Capital
B12: DCF - Exit multiple and Perpetual Growth
B13: Dividend Discount Model
B14: Sensitivity Charts
B15: Football Field
B16: Ratios
B18: Legend
... B26: This document has been done exclusively for personal use, and without Coca-Cola's supervision. May contain errors.

Sheet Drivers
C1: 2021 | D1: 2022 | E1: 2023 | F1: 2024 | G1: 2025 | H1: 2026 | I1: 2027 | J1: 2028 | K1: 2029 | L1: 2030 | M1: 2031 | N1: 2032 | O1: 2033 | P1: 2034 | Q1: 2035
B3: Revenue Drivers
B5: Base Case | S5: 2
B6: Growth by segments | H6: =+MODL!D34/100 -> 0.047258264 | I6: =+MODL!E34/100 -> 0.046633719 | J6: =+MODL!F34/100 -> 0.046689495 | K6: =+MODL!G34/100 -> 0.042408925 | L6: =+MODL!H34/100 -> 0.044995557 | M6: =+MODL!I34/100 -> 0.045092981 | N6: =+MODL!J34/100 -> 0.048022752 | O6: =+MODL!K34/100 -> 0.04281989 | ... Q6: =+MODL!M34/100 -> 0.045510235 | S6: Upside | T6: 1
B7: EMEA | H7: =+MODL!D35/100 -> 0.05795102 | I7: =+MODL!E35/100 -> 0.045261133 | J7: =+MODL!F35/100 -> 0.045518364 | K7: =+MODL!G35/100 -> 0.037190631 | L7: =+MODL!H35/100 -> 0.039820309 | M7: =+MODL!I35/100 -> 0.039818125 | N7: =+MODL!J35/100 -> 0.043566416 | O7: =+MODL!K35/100 -> 0.037197778 | ... Q7: =+MODL!M35/100 -> 0.039822394 | S7: Base | T7: 2
B8: Latin America | H8: =+MODL!D36/100 -> 0.045139482 | I8: =+MODL!E36/100 -> 0.065433257 | J8: =+MODL!F36/100 -> 0.065 | K8: =+MODL!G36/100 -> 0.065 | L8: =+MODL!H36/100 -> 0.065 | M8: =+MODL!I36/100 -> 0.065 | N8: =+MODL!J36/100 -> 0.065 | O8: =+MODL!K36/100 -> 0.065 | ... Q8: =+MODL!M36/100 -> 0.065 | S8: Downside | T8: 3
B9: North America | H9: =+MODL!D37/100 -> 0.051145989 | I9: =+MODL!E37/100 -> 0.042054848 | J9: =+MODL!F37/100 -> 0.043643297 | K9: =+MODL!G37/100 -> 0.04255804 | L9: =+MODL!H37/100 -> 0.043816365 | M9: =+MODL!I37/100 -> 0.043815331 | N9: =+MODL!J37/100 -> 0.044692868 | O9: =+MODL!K37/100 -> 0.042560639 | ... Q9: =+MODL!M37/100 -> 0.043817359
B10: Asia Pacific | H10: =+MODL!D38/100 -> 0.016135375 | I10: =+MODL!E38/100 -> 0.040113099 | J10: =+MODL!F38/100 -> 0.046312062 | K10: =+MODL!G38/100 -> 0.051487102 | L10: =+MODL!H38/100 -> 0.054339401 | M10: =+MODL!I38/100 -> 0.054336071 | N10: =+MODL!J38/100 -> 0.061215387 | O10: =+MODL!K38/100 -> 0.051500027 | ... Q10: =+MODL!M38/100 -> 0.054342565
B12: Upside Case (+0.5%) | C12: 0.005
B13: EMEA | H13: =+H7+$C$12 -> 0.06295102 | I13: =+I7+$C$12 -> 0.050261133 | J13: =+J7+$C$12 -> 0.050518364 | K13: =+K7+$C$12 -> 0.042190631 | L13: =+L7+$C$12 -> 0.044820309 | M13: =+M7+$C$12 -> 0.044818125 | N13: =+N7+$C$12 -> 0.048566416 | O13: =+O7+$C$12 -> 0.042197778 | ... Q13: =+Q7+$C$12 -> 0.044822394
B14: Latin America | H14: =+H8+$C$12 -> 0.050139482 | I14: =+I8+$C$12 -> 0.070433257 | J14: =+J8+$C$12 -> 0.07 | K14: =+K8+$C$12 -> 0.07 | L14: =+L8+$C$12 -> 0.07 | M14: =+M8+$C$12 -> 0.07 | N14: =+N8+$C$12 -> 0.07 | O14: =+O8+$C$12 -> 0.07 | ... Q14: =+Q8+$C$12 -> 0.07
B15: North America | H15: =+H9+$C$12 -> 0.056145989 | I15: =+I9+$C$12 -> 0.047054848 | J15: =+J9+$C$12 -> 0.048643297 | K15: =+K9+$C$12 -> 0.04755804 | L15: =+L9+$C$12 -> 0.048816365 | M15: =+M9+$C$12 -> 0.048815331 | N15: =+N9+$C$12 -> 0.049692868 | O15: =+O9+$C$12 -> 0.047560639 | ... Q15: =+Q9+$C$12 -> 0.048817359
B16: Asia Pacific | H16: =+H10+$C$12 -> 0.021135375 | I16: =+I10+$C$12 -> 0.045113099 | J16: =+J10+$C$12 -> 0.051312062 | K16: =+K10+$C$12 -> 0.056487102 | L16: =+L10+$C$12 -> 0.059339401 | M16: =+M10+$C$12 -> 0.059336071 | N16: =+N10+$C$12 -> 0.066215387 | O16: =+O10+$C$12 -> 0.056500027 | ... Q16: =+Q10+$C$12 -> 0.059342565
B18: Downside Case (-0.5%) | C18: 0.005
B19: EMEA | H19: =+H7-$C$18 -> 0.05295102 | I19: =+I7-$C$18 -> 0.040261133 | J19: =+J7-$C$18 -> 0.040518364 | K19: =+K7-$C$18 -> 0.032190631 | L19: =+L7-$C$18 -> 0.034820309 | M19: =+M7-$C$18 -> 0.034818125 | N19: =+N7-$C$18 -> 0.038566416 | O19: =+O7-$C$18 -> 0.032197778 | ... Q19: =+Q7-$C$18 -> 0.034822394
B20: Latin America | H20: =+H8-$C$18 -> 0.040139482 | I20: =+I8-$C$18 -> 0.060433257 | J20: =+J8-$C$18 -> 0.06 | K20: =+K8-$C$18 -> 0.06 | L20: =+L8-$C$18 -> 0.06 | M20: =+M8-$C$18 -> 0.06 | N20: =+N8-$C$18 -> 0.06 | O20: =+O8-$C$18 -> 0.06 | ... Q20: =+Q8-$C$18 -> 0.06
B21: North America | H21: =+H9-$C$18 -> 0.046145989 | I21: =+I9-$C$18 -> 0.037054848 | J21: =+J9-$C$18 -> 0.038643297 | K21: =+K9-$C$18 -> 0.03755804 | L21: =+L9-$C$18 -> 0.038816365 | M21: =+M9-$C$18 -> 0.038815331 | N21: =+N9-$C$18 -> 0.039692868 | O21: =+O9-$C$18 -> 0.037560639 | ... Q21: =+Q9-$C$18 -> 0.038817359
B22: Asia Pacific | H22: =+H10-$C$18 -> 0.011135375 | I22: =+I10-$C$18 -> 0.035113099 | J22: =+J10-$C$18 -> 0.041312062 | K22: =+K10-$C$18 -> 0.046487102 | L22: =+L10-$C$18 -> 0.049339401 | M22: =+M10-$C$18 -> 0.049336071 | N22: =+N10-$C$18 -> 0.056215387 | O22: =+O10-$C$18 -> 0.046500027 | ... Q22: =+Q10-$C$18 -> 0.049342565
B24: Active Case
B25: EMEA | H25: =+CHOOSE($S$5, H13, H7, H19) -> 0.05795102 | I25: =+CHOOSE($S$5, I13, I7, I19) -> 0.045261133 | J25: =+CHOOSE($S$5, J13, J7, J19) -> 0.045518364 | K25: =+CHOOSE($S$5, K13, K7, K19) -> 0.037190631 | L25: =+CHOOSE($S$5, L13, L7, L19) -> 0.039820309 | M25: =+CHOOSE($S$5, M13, M7, M19) -> 0.039818125 | N25: =+CHOOSE($S$5, N13, N7, N19) -> 0.043566416 | O25: =+CHOOSE($S$5, O13, O7, O19) -> 0.037197778 | ... Q25: =+CHOOSE($S$5, Q13, Q7, Q19) -> 0.039822394
B26: Latin America | H26: =+CHOOSE($S$5, H14, H8, H20) -> 0.045139482 | I26: =+CHOOSE($S$5, I14, I8, I20) -> 0.065433257 | J26: =+CHOOSE($S$5, J14, J8, J20) -> 0.065 | K26: =+CHOOSE($S$5, K14, K8, K20) -> 0.065 | L26: =+CHOOSE($S$5, L14, L8, L20) -> 0.065 | M26: =+CHOOSE($S$5, M14, M8, M20) -> 0.065 | N26: =+CHOOSE($S$5, N14, N8, N20) -> 0.065 | O26: =+CHOOSE($S$5, O14, O8, O20) -> 0.065 | ... Q26: =+CHOOSE($S$5, Q14, Q8, Q20) -> 0.065
B27: North America | H27: =+CHOOSE($S$5, H15, H9, H21) -> 0.051145989 | I27: =+CHOOSE($S$5, I15, I9, I21) -> 0.042054848 | J27: =+CHOOSE($S$5, J15, J9, J21) -> 0.043643297 | K27: =+CHOOSE($S$5, K15, K9, K21) -> 0.04255804 | L27: =+CHOOSE($S$5, L15, L9, L21) -> 0.043816365 | M27: =+CHOOSE($S$5, M15, M9, M21) -> 0.043815331 | N27: =+CHOOSE($S$5, N15, N9, N21) -> 0.044692868 | O27: =+CHOOSE($S$5, O15, O9, O21) -> 0.042560639 | ... Q27: =+CHOOSE($S$5, Q15, Q9, Q21) -> 0.043817359
B28: Asia Pacific | H28: =+CHOOSE($S$5, H16, H10, H22) -> 0.016135375 | I28: =+CHOOSE($S$5, I16, I10, I22) -> 0.040113099 | J28: =+CHOOSE($S$5, J16, J10, J22) -> 0.046312062 | K28: =+CHOOSE($S$5, K16, K10, K22) -> 0.051487102 | L28: =+CHOOSE($S$5, L16, L10, L22) -> 0.054339401 | M28: =+CHOOSE($S$5, M16, M10, M22) -> 0.054336071 | N28: =+CHOOSE($S$5, N16, N10, N22) -> 0.061215387 | O28: =+CHOOSE($S$5, O16, O10, O22) -> 0.051500027 | ... Q28: =+CHOOSE($S$5, Q16, Q10, Q22) -> 0.054342565
B31: Cost Drivers
B33: Gross Profit (Margin %) | C33: =+CR!C10/CR!C6 -> 0.60137617 | D33: =+CR!D10/CR!D6 -> 0.57759141 | E33: =+CR!E10/CR!E6 -> 0.59669317 | F33: =+CR!F10/CR!F6 -> 0.61076401 | G33: =+CR!G10/CR!G6 -> 0.61994923
B34: Upside | C34: 0.002 | H34: =+H35+C34 -> 0.6032748 | I34: =+H34+$C$34 -> 0.6052748 | J34: =+I34+$C$34 -> 0.6072748 | K34: =+J34+$C$34 -> 0.6092748 | L34: =+K34+$C$34 -> 0.6112748 | M34: =+L34+$C$34 -> 0.6132748 | N34: =+M34+$C$34 -> 0.6152748 | O34: =+N34+$C$34 -> 0.6172748 | P34: =+O34+$C$34 -> 0.6192748 | Q34: =+P34+$C$34 -> 0.6212748
B35: Base | C35: 0 | H35: =+AVERAGE($C$33:$G$33)+C35 -> 0.6012748 | I35: =+H35+$C$35 -> 0.6012748 | J35: =+I35+$C$35 -> 0.6012748 | K35: =+J35+$C$35 -> 0.6012748 | L35: =+K35+$C$35 -> 0.6012748 | M35: =+L35+$C$35 -> 0.6012748 | N35: =+M35+$C$35 -> 0.6012748 | O35: =+N35+$C$35 -> 0.6012748 | P35: =+O35+$C$35 -> 0.6012748 | Q35: =+P35+$C$35 -> 0.6012748
B36: Downside | C36: 0.001 | H36: =+H35-C36 -> 0.6002748 | I36: =+H36-$C$36 -> 0.5992748 | J36: =+I36-$C$36 -> 0.5982748 | K36: =+J36-$C$36 -> 0.5972748 | L36: =+K36-$C$36 -> 0.5962748 | M36: =+L36-$C$36 -> 0.5952748 | N36: =+M36-$C$36 -> 0.5942748 | O36: =+N36-$C$36 -> 0.5932748 | P36: =+O36-$C$36 -> 0.5922748 | Q36: =+P36-$C$36 -> 0.5912748
B37: Active | H37: =+CHOOSE($S$5, H34,H35,H36) -> 0.6012748 | I37: =+CHOOSE($S$5, I34,I35,I36) -> 0.6012748 | J37: =+CHOOSE($S$5, J34,J35,J36) -> 0.6012748 | K37: =+CHOOSE($S$5, K34,K35,K36) -> 0.6012748 | L37: =+CHOOSE($S$5, L34,L35,L36) -> 0.6012748 | M37: =+CHOOSE($S$5, M34,M35,M36) -> 0.6012748 | N37: =+CHOOSE($S$5, N34,N35,N36) -> 0.6012748 | O37: =+CHOOSE($S$5, O34,O35,O36) -> 0.6012748 | ... Q37: =+CHOOSE($S$5, Q34,Q35,Q36) -> 0.6012748
B40: SG&A to Sales % | H40: =+MODL!D179/100 -> 0.29422757 | I40: =+MODL!E179/100 -> 0.28611606 | J40: =+MODL!F179/100 -> 0.28348516 | K40: =+MODL!G179/100 -> 0.28032817 | L40: =+MODL!H179/100 -> 0.27532817 | M40: =+MODL!I179/100 -> 0.27032817 | N40: =+MODL!J179/100 -> 0.26532817 | O40: =+MODL!K179/100 -> 0.26032817 | ... Q40: =+MODL!M179/100 -> 0.25032817
B41: Upside | C41: 0.01 | H41: =+H40-$C$41 -> 0.28422757 | I41: =+I40-$C$41 -> 0.27611606 | J41: =+J40-$C$41 -> 0.27348516 | K41: =+K40-$C$41 -> 0.27032817 | L41: =+L40-$C$41 -> 0.26532817 | M41: =+M40-$C$41 -> 0.26032817 | N41: =+N40-$C$41 -> 0.25532817 | O41: =+O40-$C$41 -> 0.25032817 | ... Q41: =+Q40-$C$41 -> 0.24032817
B42: Base | C42: 0 | H42: =+H40+$C$42 -> 0.29422757 | I42: =+I40+$C$42 -> 0.28611606 | J42: =+J40+$C$42 -> 0.28348516 | K42: =+K40+$C$42 -> 0.28032817 | L42: =+L40+$C$42 -> 0.27532817 | M42: =+M40+$C$42 -> 0.27032817 | N42: =+N40+$C$42 -> 0.26532817 | O42: =+O40+$C$42 -> 0.26032817 | ... Q42: =+Q40+$C$42 -> 0.25032817
B43: Downside | C43: 0.01 | H43: =+H40+$C$43 -> 0.30422757 | I43: =+I40+$C$43 -> 0.29611606 | J43: =+J40+$C$43 -> 0.29348516 | K43: =+K40+$C$43 -> 0.29032817 | L43: =+L40+$C$43 -> 0.28532817 | M43: =+M40+$C$43 -> 0.28032817 | N43: =+N40+$C$43 -> 0.27532817 | O43: =+O40+$C$43 -> 0.27032817 | ... Q43: =+Q40+$C$43 -> 0.26032817
B44: Active | H44: =+CHOOSE($S$5,H41,H42,H43) -> 0.29422757 | I44: =+CHOOSE($S$5,I41,I42,I43) -> 0.28611606 | J44: =+CHOOSE($S$5,J41,J42,J43) -> 0.28348516 | K44: =+CHOOSE($S$5,K41,K42,K43) -> 0.28032817 | L44: =+CHOOSE($S$5,L41,L42,L43) -> 0.27532817 | M44: =+CHOOSE($S$5,M41,M42,M43) -> 0.27032817 | N44: =+CHOOSE($S$5,N41,N42,N43) -> 0.26532817 | O44: =+CHOOSE($S$5,O41,O42,O43) -> 0.26032817 | ... Q44: =+CHOOSE($S$5,Q41,Q42,Q43) -> 0.25032817
B47: D&A to Sales % | H47: =+MODL!D185/100 -> 0.023246103 | I47: =+MODL!E185/100 -> 0.025008073 | J47: =+MODL!F185/100 -> 0.025088868 | K47: =+MODL!G185/100 -> 0.028431599 | L47: =+MODL!H185/100 -> 0.028764932 | M47: =+MODL!I185/100 -> 0.028764932 | N47: =+MODL!J185/100 -> 0.028764932 | O47: =+MODL!K185/100 -> 0.028764932 | ... Q47: =+MODL!M185/100 -> 0.028764932
B48: Upside | C48: 0.003 | H48: =+H47-$C$48 -> 0.020246103 | I48: =+I47-$C$48 -> 0.022008073 | J48: =+J47-$C$48 -> 0.022088868 | K48: =+K47-$C$48 -> 0.025431599 | L48: =+L47-$C$48 -> 0.025764932 | M48: =+M47-$C$48 -> 0.025764932 | N48: =+N47-$C$48 -> 0.025764932 | O48: =+O47-$C$48 -> 0.025764932 | ... Q48: =+Q47-$C$48 -> 0.025764932
B49: Base | C49: 0 | H49: =+H47+$C$49 -> 0.023246103 | I49: =+I47+$C$49 -> 0.025008073 | J49: =+J47+$C$49 -> 0.025088868 | K49: =+K47+$C$49 -> 0.028431599 | L49: =+L47+$C$49 -> 0.028764932 | M49: =+M47+$C$49 -> 0.028764932 | N49: =+N47+$C$49 -> 0.028764932 | O49: =+O47+$C$49 -> 0.028764932 | ... Q49: =+Q47+$C$49 -> 0.028764932
B50: Downside | C50: 0.003 | H50: =+H47+$C$50 -> 0.026246103 | I50: =+I47+$C$50 -> 0.028008073 | J50: =+J47+$C$50 -> 0.028088868 | K50: =+K47+$C$50 -> 0.031431599 | L50: =+L47+$C$50 -> 0.031764932 | M50: =+M47+$C$50 -> 0.031764932 | N50: =+N47+$C$50 -> 0.031764932 | O50: =+O47+$C$50 -> 0.031764932 | ... Q50: =+Q47+$C$50 -> 0.031764932
B51: Active | H51: =+CHOOSE($S$5,H48,H49,H50) -> 0.023246103 | I51: =+CHOOSE($S$5,I48,I49,I50) -> 0.025008073 | J51: =+CHOOSE($S$5,J48,J49,J50) -> 0.025088868 | K51: =+CHOOSE($S$5,K48,K49,K50) -> 0.028431599 | L51: =+CHOOSE($S$5,L48,L49,L50) -> 0.028764932 | M51: =+CHOOSE($S$5,M48,M49,M50) -> 0.028764932 | N51: =+CHOOSE($S$5,N48,N49,N50) -> 0.028764932 | O51: =+CHOOSE($S$5,O48,O49,O50) -> 0.028764932 | ... Q51: =+CHOOSE($S$5,Q48,Q49,Q50) -> 0.028764932
B54: Mergers and Acquisitions | C54: =+CR!C26 -> -1173 | D54: =+CR!D26 -> 408 | E54: =+CR!E26 -> 836 | F54: =+CR!F26 -> 1377 | G54: =+CR!G26 -> -654
...

Sheet Debt
B3: 1. Current Debt Summary (as of 12/31/2025)
B4: Instrument | C4: Amount | D4: Avg Rate | E4: Maturity
B5: Commercial paper | C5: 1495 | D5: 0.039 | E5: <1 yr
B6: Lines of credit / other ST | C6: 56 | D6: 0.039 | E6: <1 yr
B7: Short-term borrowings (CP + LOC) | C7: =SUM(C5:C6) -> 1551
B8: U.S. dollar notes due 2027-2093 | C8: 26945 | D8: 0.036
B9: U.S. dollar debentures due 2026-2098 | C9: 767 | D9: 0.048
B10: Euro notes due 2026-2053 | C10: 15470 | D10: 0.024
B11: Swiss franc notes due 2028 | C11: 726 | D11: 0.051
B12: Other, due through 2098 | C12: 651 | D12: 0.049
B13: Fair value adjustments | C13: -618
B14: Total long-term debt (incl. current) | C14: =SUM(C8:C13) -> 43941 | D14: =+Drivers!C148 -> 0.033
B15: Less: current portion of LTD | C15: -1822
B16: Noncurrent long-term debt | C16: =C14+C15 -> 42119
B18: 2. Operating Leases (as of 12/31/2025)
B19: Item | C19: Amount
B20: Operating lease ROU assets | C20: 1697
B21: Current portion of lease liabilities | C21: 321
B22: Noncurrent portion of lease liabilities | C22: 1401
B23: Total operating lease liabilities | C23: =C21+C22 -> 1722
B24: Weighted-avg discount rate | C24: 0.039
B25: Annual operating lease cost (2025) | C25: 405
B27: 3. Maturity Schedule
B28: Year | C28: LTD Maturities | D28: Lease Payments
B29: 2026 | C29: 1822 | D29: 381
B30: 2027 | C30: 4817 | D30: 317
B31: 2028 | C31: 2923 | D31: 259
B32: 2029 | C32: 2955 | D32: 213
B33: 2030 | C33: 3411 | D33: 170
B34: Thereafter | D34: 679
B35: Total lease payments | D35: =SUM(D29:D34) -> 2019
B36: Less: imputed interest | D36: -297
B37: Total lease liabilities (PV) | D37: =D35+D36 -> 1722
B39: 4. Projected Roll-Forward (Target Leverage)
B40: Target LTD / EBITDA | C40: =+Drivers!H139 -> 2.79 | D40: =+Drivers!I139 -> 2.72 | E40: =+Drivers!J139 -> 2.65 | F40: =+Drivers!K139 -> 2.58 | G40: =+Drivers!L139 -> 2.5 | H40: =+Drivers!M139 -> 2.5 | I40: =+Drivers!N139 -> 2.5 | J40: =+Drivers!O139 -> 2.5 | ... L40: =+Drivers!Q139 -> 2.5
C41: 2026 | D41: 2027 | E41: 2028 | F41: 2029 | G41: 2030 | H41: 2031 | I41: 2032 | J41: 2033 | K41: 2034 | L41: 2035 | M41: 2036
B42: Long-Term Debt
B43: Opening balance | C43: =C14 -> 43941 | D43: =C46 -> 43941 | E43: =D46 -> 43941 | F43: =E46 -> 43941 | G43: =F46 -> 43941 | H43: =G46 -> 43941 | I43: =H46 -> 43941 | J43: =I46 -> 43941 | K43: =J46 -> 43941 | ... M43: =L46 -> 43941
B44: Less: maturities (repayments) | C44: =-C29 -> -1822 | D44: =-C30 -> -4817 | E44: =-C31 -> -2923 | F44: =-C32 -> -2955 | G44: =-C33 -> -3411 | H44: 0 | I44: 0 | J44: 0 | K44: 0 | L44: 0 | M44: =-L29 -> 0
B45: Add: new issuance (refinancing) | C45: =C46-C43-C44 -> 1822 | D45: =D46-D43-D44 -> 4817 | E45: =E46-E43-E44 -> 2923 | F45: =F46-F43-F44 -> 2955 | G45: =G46-G43-G44 -> 3411 | H45: =H46-H43-H44 -> 0 | I45: =I46-I43-I44 -> 0 | J45: =J46-J43-J44 -> 0 | ... L45: =L46-L43-L44 -> 0 | M45: =-M44*$C$40 -> 0
...

Sheet IS
C1: 2021 | D1: 2022 | E1: 2023 | F1: 2024 | G1: 2025 | H1: 2026 | I1: 2027 | J1: 2028 | K1: 2029 | L1: 2030 | M1: 2031 | N1: 2032 | O1: 2033 | P1: 2034 | Q1: 2035
B3: Income Statement
B5: Total Revenue | C5: =+CR!C6 -> 38658 | D5: =+CR!D6 -> 43046 | E5: =+CR!E6 -> 45784 | F5: =+CR!F6 -> 46897 | G5: =+CR!G6 -> 48062 | H5: =+H6+H8+H10+H12+H14 -> 49135.18 | I5: =+I6+I8+I10+I12+I14 -> 49847.891 | J5: =+J6+J8+J10+J12+J14 -> 52374.969 | K5: =+K6+K8+K10+K12+K14 -> 55028.626 | L5: =+L6+L8+L10+L12+L14 -> 57564.081 | M5: =+M6+M8+M10+M12+M14 -> 60285.97 | N5: =+N6+N8+N10+N12+N14 -> 63140.657 | O5: =+O6+O8+O10+O12+O14 -> 66269.178 | ... Q5: =+Q6+Q8+Q10+Q12+Q14 -> 72612.841
B6: EMEA | H6: =+MODL!D22 -> 12228.31 | I6: =+H6*(1+H7) -> 12936.953 | J6: =+I6*(1+I7) -> 13522.494 | K6: =+J6*(1+J7) -> 14138.016 | L6: =+K6*(1+K7) -> 14663.818 | M6: =+L6*(1+L7) -> 15247.736 | N6: =+M6*(1+M7) -> 15854.872 | O6: =+N6*(1+N7) -> 16545.612 | P6: =+O6*(1+O7) -> 17161.072 | Q6: =+P6*(1+P7) -> 17844.504
B7: YoY growth % | H7: =+Drivers!H7 -> 0.05795102 | I7: =+Drivers!I7 -> 0.045261133 | J7: =+Drivers!J7 -> 0.045518364 | K7: =+Drivers!K7 -> 0.037190631 | L7: =+Drivers!L7 -> 0.039820309 | M7: =+Drivers!M7 -> 0.039818125 | N7: =+Drivers!N7 -> 0.043566416 | O7: =+Drivers!O7 -> 0.037197778 | ... Q7: =+Drivers!Q7 -> 0.039822394
B8: Latin America | H8: =+MODL!D23 -> 6858.39 | I8: =+H8*(1+H9) -> 7167.9741 | J8: =+I8*(1+I9) -> 7636.998 | K8: =+J8*(1+J9) -> 8133.4029 | L8: =+K8*(1+K9) -> 8662.0741 | M8: =+L8*(1+L9) -> 9225.1089 | N8: =+M8*(1+M9) -> 9824.741 | O8: =+N8*(1+N9) -> 10463.349 | P8: =+O8*(1+O9) -> 11143.467 | Q8: =+P8*(1+P9) -> 11867.792
B9: YoY growth % | H9: =+Drivers!H8 -> 0.045139482 | I9: =+Drivers!I8 -> 0.065433257 | J9: =+Drivers!J8 -> 0.065 | K9: =+Drivers!K8 -> 0.065 | L9: =+Drivers!L8 -> 0.065 | M9: =+Drivers!M8 -> 0.065 | N9: =+Drivers!N8 -> 0.065 | O9: =+Drivers!O8 -> 0.065 | ... Q9: =+Drivers!Q8 -> 0.065
B10: North America | H10: =+MODL!D24 -> 20552.014 | I10: =+H10*(1+H11) -> 21603.167 | J10: =+I10*(1+I11) -> 22511.685 | K10: =+J10*(1+J11) -> 23494.169 | L10: =+K10*(1+K11) -> 24494.035 | M10: =+L10*(1+L11) -> 25567.275 | N10: =+M10*(1+M11) -> 26687.513 | O10: =+N10*(1+N11) -> 27880.255 | P10: =+O10*(1+O11) -> 29066.856 | Q10: =+P10*(1+P11) -> 30340.519
B11: YoY growth % | H11: =+Drivers!H9 -> 0.051145989 | I11: =+Drivers!I9 -> 0.042054848 | J11: =+Drivers!J9 -> 0.043643297 | K11: =+Drivers!K9 -> 0.04255804 | L11: =+Drivers!L9 -> 0.043816365 | M11: =+Drivers!M9 -> 0.043815331 | N11: =+Drivers!N9 -> 0.044692868 | O11: =+Drivers!O9 -> 0.042560639 | ... Q11: =+Drivers!Q9 -> 0.043817359
B12: Asia Pacific | H12: =+MODL!D25 -> 5779.3126 | I12: =+H12*(1+H13) -> 5872.564 | J12: =+I12*(1+I13) -> 6108.1307 | K12: =+J12*(1+J13) -> 6391.0108 | L12: =+K12*(1+K13) -> 6720.0654 | M12: =+L12*(1+L13) -> 7085.2298 | N12: =+M12*(1+M13) -> 7470.2133 | O12: =+N12*(1+N13) -> 7927.5053 | P12: =+O12*(1+O13) -> 8335.7721 | Q12: =+P12*(1+P13) -> 8788.7869
B13: YoY growth % | H13: =+Drivers!H10 -> 0.016135375 | I13: =+Drivers!I10 -> 0.040113099 | J13: =+Drivers!J10 -> 0.046312062 | K13: =+Drivers!K10 -> 0.051487102 | L13: =+Drivers!L10 -> 0.054339401 | M13: =+Drivers!M10 -> 0.054336071 | N13: =+Drivers!N10 -> 0.061215387 | O13: =+Drivers!O10 -> 0.051500027 | ... Q13: =+Drivers!Q10 -> 0.054342565
B14: Bottling & Other | H14: =+MODL!D18+MODL!D19+MODL!D20 -> 3717.1536 | I14: =+MODL!E18+MODL!E19+MODL!E20 -> 2267.2327 | J14: =+MODL!F18+MODL!F19+MODL!F20 -> 2595.6606 | K14: =+MODL!G18+MODL!G19+MODL!G20 -> 2872.0271 | L14: =+MODL!H18+MODL!H19+MODL!H20 -> 3024.0884 | M14: =+L14*(1+AVERAGE($H$7:$L$7)) -> 3160.6208 | N14: =+M14*(1+AVERAGE($H$7:$L$7)) -> 3303.3174 | O14: =+N14*(1+AVERAGE($H$7:$L$7)) -> 3452.4565 | P14: =+O14*(1+AVERAGE($H$7:$L$7)) -> 3608.3291 | Q14: =+P14*(1+AVERAGE($H$7:$L$7)) -> 3771.2389
B16: Cost of Goods Sold (COGS) | C16: =+C5-C18 -> 15410 | D16: =+D5-D18 -> 18183 | E16: =+E5-E18 -> 18465 | F16: =+F5-F18 -> 18254 | G16: =+G5-G18 -> 18266 | H16: =+H5-H18 -> 19591.435 | I16: =+I5-I18 -> 19875.61 | J16: =+J5-J18 -> 20883.22 | ... Q16: =+Q5-Q18 -> 28952.57
B18: Gross Profit | C18: =+CR!C10 -> 23248 | D18: =+CR!D10 -> 24863 | E18: =+CR!E10 -> 27319 | F18: =+CR!F10 -> 28643 | G18: =+CR!G10 -> 29796 | H18: =+H19*H5 -> 29543.746 | I18: =+I19*I5 -> 29972.281 | J18: =+J19*J5 -> 31491.749 | K18: =+K19*K5 -> 33087.326 | L18: =+L19*L5 -> 34611.831 | M18: =+M19*M5 -> 36248.434 | N18: =+N19*N5 -> 37964.886 | O18: =+O19*O5 -> 39845.987 | ... Q18: =+Q19*Q5 -> 43660.272
B19: Gross Profit Margin % | C19: =+C18/C5 -> 0.60137617 | D19: =+D18/D5 -> 0.57759141 | E19: =+E18/E5 -> 0.59669317 | F19: =+F18/F5 -> 0.61076401 | G19: =+G18/G5 -> 0.61994923 | H19: =+Drivers!H37 -> 0.6012748 | I19: =+Drivers!I37 -> 0.6012748 | J19: =+Drivers!J37 -> 0.6012748 | K19: =+Drivers!K37 -> 0.6012748 | L19: =+Drivers!L37 -> 0.6012748 | M19: =+Drivers!M37 -> 0.6012748 | N19: =+Drivers!N37 -> 0.6012748 | O19: =+Drivers!O37 -> 0.6012748 | ... Q19: =+Drivers!Q37 -> 0.6012748
B21: SG&A expenses | C21: =+CR!C12 -> 12139 | D21: =+CR!D12 -> 12263 | E21: =+CR!E12 -> 13983 | F21: =+CR!F12 -> 17996 | G21: =+CR!G12 -> 15481 | H21: =+H22*H5 -> 14456.925 | I21: =+I22*I5 -> 14262.282 | J21: =+J22*J5 -> 14847.526 | K21: =+K22*K5 -> 15426.074 | L21: =+L22*L5 -> 15849.013 | M21: =+M22*M5 -> 16296.996 | N21: =+N22*N5 -> 16752.995 | O21: =+O22*O5 -> 17251.734 | ... Q21: =+Q22*Q5 -> 18177.04
B22: SG&A % of Revenue | C22: =+C21/C5 -> 0.31401004 | D22: =+D21/D5 -> 0.28488129 | E22: =+E21/E5 -> 0.30541237 | F22: =+F21/F5 -> 0.38373457 | G22: =+G21/G5 -> 0.32210478 | H22: =+Drivers!H44 -> 0.29422757 | I22: =+Drivers!I44 -> 0.28611606 | J22: =+Drivers!J44 -> 0.28348516 | K22: =+Drivers!K44 -> 0.28032817 | L22: =+Drivers!L44 -> 0.27532817 | M22: =+Drivers!M44 -> 0.27032817 | N22: =+Drivers!N44 -> 0.26532817 | O22: =+Drivers!O44 -> 0.26032817 | ... Q22: =+Drivers!Q44 -> 0.25032817
B24: Depreciation & Amortization | C24: Included on SG&A expenses | H24: =+H25*H5 -> 1142.2015 | I24: =+I25*I5 -> 1246.5997 | J24: =+J25*J5 -> 1314.0287 | K24: =+K25*K5 -> 1564.5518 | L24: =+L25*L5 -> 1655.8269 | M24: =+M25*M5 -> 1734.1218 | N24: =+N25*N5 -> 1816.2367 | O24: =+O25*O5 -> 1906.2284 | ... Q24: =+Q25*Q5 -> 2088.7035
B25: D&A % of Revenue | H25: =+Drivers!H51 -> 0.023246103 | I25: =+Drivers!I51 -> 0.025008073 | J25: =+Drivers!J51 -> 0.025088868 | K25: =+Drivers!K51 -> 0.028431599 | L25: =+Drivers!L51 -> 0.028764932 | M25: =+Drivers!M51 -> 0.028764932 | N25: =+Drivers!N51 -> 0.028764932 | O25: =+Drivers!O51 -> 0.028764932 | ... Q25: =+Drivers!Q51 -> 0.028764932
B27: Operating income (EBIT) | C27: =+CR!C16 -> 11109 | D27: =+CR!D16 -> 12600 | E27: =+CR!E16 -> 13336 | F27: =+CR!F16 -> 10647 | G27: =+CR!G16 -> 14315 | H27: =+H18-H21-H24 -> 13944.62 | I27: =+I18-I21-I24 -> 14463.399 | J27: =+J18-J21-J24 -> 15330.194 | K27: =+K18-K21-K24 -> 16096.7 | L27: =+L18-L21-L24 -> 17106.991 | M27: =+M18-M21-M24 -> 18217.317 | N27: =+N18-N21-N24 -> 19395.654 | O27: =+O18-O21-O24 -> 20688.024 | ... Q27: =+Q18-Q21-Q24 -> 23394.528
B28: EBIT % of Revenue | C28: =+C27/C5 -> 0.28736613 | D28: =+D27/D5 -> 0.29271012 | E28: =+E27/E5 -> 0.2912808 | F28: =+F27/F5 -> 0.22702945 | G28: =+G27/G5 -> 0.29784445 | H28: =+H27/H5 -> 0.28380113 | I28: =+I27/I5 -> 0.29015067 | J28: =+J27/J5 -> 0.29270078 | ... Q28: =+Q27/Q5 -> 0.3221817
B30: Non-operation expenses | C30: =+SUM(C31:C33) -> -1594 | D30: =+SUM(D31:D33) -> -2746 | E30: =+SUM(E31:E33) -> -630 | F30: =+SUM(F31:F33) -> -1242 | G30: =+SUM(G31:G33) -> -1808 | H30: =+SUM(H31:H33) -> 293.3 | I30: =+SUM(I31:I33) -> 293.3 | J30: =+SUM(J31:J33) -> 293.3 | ... Q30: =+SUM(Q31:Q33) -> 293.3
B31: Restructuring charges | C31: =+CR!C28 -> 378 | D31: =+CR!D28 -> 117 | E31: =+CR!E28 -> 191 | F31: =+CR!F28 -> 133 | G31: =+CR!G28 -> 97 | H31: =+Drivers!H61 -> 134.5 | I31: =+Drivers!I61 -> 134.5 | J31: =+Drivers!J61 -> 134.5 | K31: =+Drivers!K61 -> 134.5 | L31: =+Drivers!L61 -> 134.5 | M31: =+Drivers!M61 -> 134.5 | N31: =+Drivers!N61 -> 134.5 | O31: =+Drivers!O61 -> 134.5 | ... Q31: =+Drivers!Q61 -> 134.5
B32: Mergers & acquisitions | C32: =+CR!C26 -> -1173 | D32: =+CR!D26 -> 408 | E32: =+CR!E26 -> 836 | F32: =+CR!F26 -> 1377 | G32: =+CR!G26 -> -654 | H32: =+Drivers!H58 -> 158.8 | I32: =+Drivers!I58 -> 158.8 | J32: =+Drivers!J58 -> 158.8 | K32: =+Drivers!K58 -> 158.8 | L32: =+Drivers!L58 -> 158.8 | M32: =+Drivers!M58 -> 158.8 | N32: =+Drivers!N58 -> 158.8 | O32: =+Drivers!O58 -> 158.8 | ... Q32: =+Drivers!Q58 -> 158.8
B33: Other non-recurring items | C33: =-SUM(CR!C25,CR!C27,CR!C29,CR!C30) -> -799 | D33: =-SUM(CR!D25,CR!D27,CR!D29,CR!D30) -> -3271 | E33: =-SUM(CR!E25,CR!E27,CR!E29,CR!E30) -> -1657 | F33: =-SUM(CR!F25,CR!F27,CR!F29,CR!F30) -> -2752 | G33: =-SUM(CR!G25,CR!G27,CR!G29,CR!G30) -> -1251 | H33: 0 | I33: 0 | J33: 0 | K33: 0 | L33: 0 | M33: 0 | N33: 0 | O33: 0 | P33: 0 | Q33: 0
B35: Net interest expense | C35: =+CR!C18 -> 2142 | D35: =+SUM(D36:D39) -> 1307 | E35: =+SUM(E36:E39) -> 2459 | F35: =+SUM(F36:F39) -> 2669 | G35: =+SUM(G36:G39) -> 2415 | H35: =+SUM(H36:H39) -> 725.08069 | I35: =+SUM(I36:I39) -> 753.41086 | J35: =+SUM(J36:J39) -> 742.1407 | K35: =+SUM(K36:K39) -> 745.67183 | ... Q35: =+SUM(Q36:Q39) -> 769.34317
B36: Paper notes | C36: =+CR!C19 -> 2418 | D36: =+CR!D19 -> 858 | E36: =+CR!E19 -> 1552 | F36: =+CR!F19 -> 1681 | G36: =+CR!G19 -> 1629 | H36: =+Debt!$C$7*Debt!$D$5 -> 60.489 | I36: =+Debt!$C$7*Debt!$D$5 -> 60.489 | J36: =+Debt!$C$7*Debt!$D$5 -> 60.489 | K36: =+Debt!$C$7*Debt!$D$5 -> 60.489 | L36: =+Debt!$C$7*Debt!$D$5 -> 60.489 | M36: =+Debt!$C$7*Debt!$D$5 -> 60.489 | N36: =+Debt!$C$7*Debt!$D$5 -> 60.489 | O36: =+Debt!$C$7*Debt!$D$5 -> 60.489 | ... Q36: =+Debt!$C$7*Debt!$D$5 -> 60.489
B37: LT Debt | H37: =+Debt!C47 -> 1450.053 | I37: =+Debt!D47 -> 1450.053 | J37: =+Debt!E47 -> 1450.053 | K37: =+Debt!F47 -> 1450.053 | L37: =+Debt!G47 -> 1450.053 | M37: =+Debt!H47 -> 1450.053 | N37: =+Debt!I47 -> 1450.053 | O37: =+Debt!J47 -> 1450.053 | ... Q37: =+Debt!L47 -> 1450.053
B38: Lease Liabilities | H38: =+Debt!C52 -> 67.158 | I38: =+Debt!D52 -> 68.657577 | J38: =+Debt!E52 -> 69.653462 | K38: =+Debt!F52 -> 73.184598 | L38: =+Debt!G52 -> 76.892607 | M38: =+Debt!H52 -> 80.435449 | N38: =+Debt!I52 -> 84.238799 | O38: =+Debt!J52 -> 88.227711 | ... Q38: =+Debt!L52 -> 96.855938
B39: Interest on Cashs and STI | C39: =+CR!C20 -> 276 | D39: =+CR!D20 -> 449 | E39: =+CR!E20 -> 907 | F39: =+CR!F20 -> 988 | G39: =+CR!G20 -> 786 | H39: =-Drivers!$H$142*(BS!G7+BS!G8) -> -852.61931 | I39: =-Drivers!$H$142*(BS!H7+BS!H8) -> -825.78871 | J39: =-Drivers!$H$142*(BS!I7+BS!I8) -> -838.05477 | K39: =-Drivers!$H$142*(BS!J7+BS!J8) -> -838.05477 | L39: =-Drivers!$H$142*(BS!K7+BS!K8) -> -838.05477 | M39: =-Drivers!$H$142*(BS!L7+BS!L8) -> -838.05477 | N39: =-Drivers!$H$142*(BS!M7+BS!M8) -> -838.05477 | O39: =-Drivers!$H$142*(BS!N7+BS!N8) -> -838.05477 | ... Q39: =-Drivers!$H$142*(BS!P7+BS!P8) -> -838.05477
B41: Income before taxes (EBT) | C41: =+CR!C31 -> 12425 | D41: =+CR!D31 -> 11686 | E41: =+CR!E31 -> 12952 | F41: =+CR!F31 -> 13086 | G41: =+CR!G31 -> 15998 | H41: =+H27-H30-H35 -> 12926.239 | I41: =+I27-I30-I35 -> 13416.688 | J41: =+J27-J30-J35 -> 14294.753 | K41: =+K27-K30-K35 -> 15057.728 | L41: =+L27-L30-L35 -> 16064.311 | M41: =+M27-M30-M35 -> 17171.094 | N41: =+N27-N30-N35 -> 18345.628 | O41: =+O27-O30-O35 -> 19634.009 | ... Q41: =+Q27-Q30-Q35 -> 22331.885
B43: Income taxes | C43: =+CR!C32 -> 2621 | D43: =+CR!D32 -> 2115 | E43: =+CR!E32 -> 2249 | F43: =+CR!F32 -> 2437 | G43: =+CR!G32 -> 2861 | H43: =+H44*H41 -> 2405.9273 | I43: =+I44*I41 -> 2497.2133 | J43: =+J44*J41 -> 2660.6453 | K43: =+K44*K41 -> 2802.6559 | L43: =+L44*L41 -> 2990.0086 | M43: =+M44*M41 -> 3196.0111 | N43: =+N44*N41 -> 3414.6241 | O43: =+O44*O41 -> 3654.4272 | ... Q43: =+Q44*Q41 -> 4156.5758
B44: Tax % of EBT | C44: =+C43/C41 -> 0.21094567 | D44: =+D43/D41 -> 0.18098579 | E44: =+E43/E41 -> 0.17364114 | F44: =+F43/F41 -> 0.18622956 | G44: =+G43/G41 -> 0.17883485 | H44: =+Drivers!H68 -> 0.1861274 | I44: =+Drivers!I68 -> 0.1861274 | J44: =+Drivers!J68 -> 0.1861274 | K44: =+Drivers!K68 -> 0.1861274 | L44: =+Drivers!L68 -> 0.1861274 | M44: =+Drivers!M68 -> 0.1861274 | N44: =+Drivers!N68 -> 0.1861274 | O44: =+Drivers!O68 -> 0.1861274 | ... Q44: =+Drivers!Q68 -> 0.1861274
B46: Net Income | C46: =+C41-C43 -> 9804 | D46: =+D41-D43 -> 9571 | E46: =+E41-E43 -> 10703 | F46: =+F41-F43 -> 10649 | G46: =+G41-G43 -> 13137 | H46: =+H41-H43 -> 10520.312 | I46: =+I41-I43 -> 10919.475 | J46: =+J41-J43 -> 11634.108 | ... Q46: =+Q41-Q43 -> 18175.309
B47: Net Income % of Revenue | C47: =+C46/C5 -> 0.25360857 | D47: =+D46/D5 -> 0.22234354 | E47: =+E46/E5 -> 0.23377162 | F47: =+F46/F5 -> 0.22707209 | G47: =+G46/G5 -> 0.27333444 | H47: =+H46/H5 -> 0.21410956 | I47: =+I46/I5 -> 0.2190559 | J47: =+J46/J5 -> 0.22213107 | ... Q47: =+Q46/Q5 -> 0.25030434
B49: Minority & Non-controlling interest | C49: =+CR!C40 -> 33 | D49: =+CR!D40 -> 29 | E49: =+CR!E40 -> -11 | F49: =+CR!F40 -> 18 | G49: =+CR!G40 -> 30
B51: Net Income GAAP | C51: =+C46-C49 -> 9771 | D51: =+D46-D49 -> 9542 | E51: =+E46-E49 -> 10714 | F51: =+F46-F49 -> 10631 | G51: =+G46-G49 -> 13107 | H51: =+H46-H49 -> 10520.312 | I51: =+I46-I49 -> 10919.475 | J51: =+J46-J49 -> 11634.108 | ... Q51: =+Q46-Q49 -> 18175.309
B52: Net Income GAAP % of Revenue | C52: =+C51/C5 -> 0.25275493 | D52: =+D51/D5 -> 0.22166984 | E52: =+E51/E5 -> 0.23401188 | F52: =+F51/F5 -> 0.22668827 | G52: =+G51/G5 -> 0.27271025 | H52: =+H51/H5 -> 0.21410956 | I52: =+I51/I5 -> 0.2190559 | J52: =+J51/J5 -> 0.22213107 | ... Q52: =+Q51/Q5 -> 0.25030434
B54: EPS | C54: =+C51/C55 -> 2.2644264 | D54: =+D51/D55 -> 2.2047135 | E54: =+E51/E55 -> 2.4783715 | F54: =+F51/F55 -> 2.4671618 | G54: =+G51/G55 -> 3.0460144 | H54: =+H51/H55 -> 2.4448784 | I54: =+I51/I55 -> 2.5376423 | J54: =+J51/J55 -> 2.7183737 | ... Q54: =+Q51/Q55 -> 4.4756312
B55: Basic Shares Outstanding | C55: =+CR!C50 -> 4315 | D55: =+CR!D50 -> 4328 | E55: =+CR!E50 -> 4323 | F55: =+CR!F50 -> 4309 | G55: =+CR!G50 -> 4303 | H55: =+Drivers!H130 -> 4303 | I55: =+Drivers!I130 -> 4303 | J55: =+Drivers!J130 -> 4279.8045 | K55: =+Drivers!K130 -> 4251.1295 | L55: =+Drivers!L130 -> 4220.776 | M55: =+Drivers!M130 -> 4190.0364 | N55: =+Drivers!N130 -> 4158.6376 | O55: =+Drivers!O130 -> 4126.6764 | ... Q55: =+Drivers!Q130 -> 4060.9489
...

Sheet CF
C1: 2021 | D1: 2022 | E1: 2023 | F1: 2024 | G1: 2025 | H1: 2026 | I1: 2027 | J1: 2028 | K1: 2029 | L1: 2030 | M1: 2031 | N1: 2032 | O1: 2033 | P1: 2034 | Q1: 2035
B3: Cash Flow Statement
B5: Cash From Operations (CFO)
B7: Net Income | C7: =+FC!C7 -> 9771 | D7: =+FC!D7 -> 9542 | E7: =+FC!E7 -> 10714 | F7: =+FC!F7 -> 10631 | G7: =+FC!G7 -> 13107 | H7: =+IS!H46 -> 10520.312 | I7: =+IS!I46 -> 10919.475 | J7: =+IS!J46 -> 11634.108 | K7: =+IS!K46 -> 12255.073 | L7: =+IS!L46 -> 13074.303 | M7: =+IS!M46 -> 13975.083 | N7: =+IS!N46 -> 14931.004 | O7: =+IS!O46 -> 15979.582 | ... Q7: =+IS!Q46 -> 18175.309
B8: Depreciation & Amortisation | C8: =+FC!C8 -> 1452 | D8: =+FC!D8 -> 1260 | E8: =+FC!E8 -> 1128 | F8: =+FC!F8 -> 1075 | G8: =+FC!G8 -> 1050 | H8: =+IS!H24 -> 1142.2015 | I8: =+IS!I24 -> 1246.5997 | J8: =+IS!J24 -> 1314.0287 | K8: =+IS!K24 -> 1564.5518 | L8: =+IS!L24 -> 1655.8269 | M8: =+IS!M24 -> 1734.1218 | N8: =+IS!N24 -> 1816.2367 | O8: =+IS!O24 -> 1906.2284 | ... Q8: =+IS!Q24 -> 2088.7035
B9: Stock-Based Compensation (SBC) | C9: =+FC!C10 -> 337 | D9: =+FC!D10 -> 356 | E9: =+FC!E10 -> 254 | F9: =+FC!F10 -> 286 | G9: =+FC!G10 -> 279 | H9: =+Drivers!H122*IS!H5 -> 285.82365 | I9: =+Drivers!I122*IS!I5 -> 289.96955 | J9: =+Drivers!J122*IS!J5 -> 304.66978 | K9: =+Drivers!K122*IS!K5 -> 320.10634 | L9: =+Drivers!L122*IS!L5 -> 334.8553 | M9: =+Drivers!M122*IS!M5 -> 350.68876 | N9: =+Drivers!N122*IS!N5 -> 367.29473 | O9: =+Drivers!O122*IS!O5 -> 385.49361 | ... Q9: =+Drivers!Q122*IS!Q5 -> 422.39525
B10: Deferred Taxes | C10: =+FC!C11 -> 894 | D10: =+FC!D11 -> -122 | E10: =+FC!E11 -> -2 | F10: =+FC!F11 -> -11 | G10: =+FC!G11 -> 517 | H10: =+Drivers!H124*IS!H43 -> 140.58877 | I10: =+Drivers!I124*IS!I43 -> 145.92301 | J10: =+Drivers!J124*IS!J43 -> 155.47305 | K10: =+Drivers!K124*IS!K43 -> 163.77134 | L10: =+Drivers!L124*IS!L43 -> 174.71917 | M10: =+Drivers!M124*IS!M43 -> 186.7568 | N10: =+Drivers!N124*IS!N43 -> 199.5313 | O10: =+Drivers!O124*IS!O43 -> 213.54404 | ... Q10: =+Drivers!Q124*IS!Q43 -> 242.88676
B11: ΔNWC | C11: =+FC!C13 -> 1325 | D11: =+FC!D13 -> -605 | E11: =+FC!E13 -> -846 | F11: =+FC!F13 -> -6234 | G11: =+FC!G13 -> -7208 | H11: =+SUM(H12:H16) -> -669.80549 | I11: =+SUM(I12:I16) -> 105.72115 | J11: =+SUM(J12:J16) -> 345.4533 | K11: =+SUM(K12:K16) -> 357.3238 | L11: =+SUM(L12:L16) -> 350.88853 | M11: =+SUM(M12:M16) -> 377.58402 | N11: =+SUM(N12:N16) -> 396.47568 | O11: =+SUM(O12:O16) -> 434.54764 | ... Q11: =+SUM(Q12:Q16) -> 459.59419
B12: ΔAccounts Receivable (AR) | H12: =+-(BS!H9-BS!G9) -> -751.77142 | I12: =+-(BS!I9-BS!H9) -> -54.971017 | J12: =+-(BS!J9-BS!I9) -> -194.91221 | K12: =+-(BS!K9-BS!J9) -> -204.67525 | L12: =+-(BS!L9-BS!K9) -> -195.55832 | M12: =+-(BS!M9-BS!L9) -> -209.9379 | N12: =+-(BS!N9-BS!M9) -> -220.18056 | O12: =+-(BS!O9-BS!N9) -> -241.30121 | ... Q12: =+-(BS!Q9-BS!P9) -> -254.32256
B13: ΔInventory | H13: =+-(BS!H10-BS!G10) -> -258.128 | I13: =+-(BS!I10-BS!H10) -> -67.929245 | J13: =+-(BS!J10-BS!I10) -> -240.85854 | K13: =+-(BS!K10-BS!J10) -> -252.92301 | L13: =+-(BS!L10-BS!K10) -> -241.65696 | M13: =+-(BS!M10-BS!L10) -> -259.42622 | N13: =+-(BS!N10-BS!M10) -> -272.08336 | O13: =+-(BS!O10-BS!N10) -> -298.18275 | ... Q13: =+-(BS!Q10-BS!P10) -> -314.2736
B14: ΔAccounts Payable (AP) | H14: =+(BS!H24-BS!G24) -> 233.04441 | I14: =+(BS!I24-BS!H24) -> 85.319648 | J14: =+(BS!J24-BS!I24) -> 302.52016 | K14: =+(BS!K24-BS!J24) -> 317.67323 | L14: =+(BS!L24-BS!K24) -> 303.52298 | M14: =+(BS!M24-BS!L24) -> 325.84131 | N14: =+(BS!N24-BS!M24) -> 341.73877 | O14: =+(BS!O24-BS!N24) -> 374.5198 | ... Q14: =+(BS!Q24-BS!P24) -> 394.73003
B15: ΔAccruals | H15: =+(BS!H25-BS!G25) -> 190.5564 | I15: =+(BS!I25-BS!H25) -> 126.55057 | J15: =+(BS!J25-BS!I25) -> 448.71375 | K15: =+(BS!K25-BS!J25) -> 471.18957 | L15: =+(BS!L25-BS!K25) -> 450.20118 | M15: =+(BS!M25-BS!L25) -> 483.3049 | N15: =+(BS!N25-BS!M25) -> 506.88485 | O15: =+(BS!O25-BS!N25) -> 555.50739 | ... Q15: =+(BS!Q25-BS!P25) -> 585.48426
B16: ΔTaxes Payable | H16: =+(BS!H26-BS!G26) -> -83.506877 | I16: =+(BS!I26-BS!H26) -> 16.751193 | J16: =+(BS!J26-BS!I26) -> 29.990144 | K16: =+(BS!K26-BS!J26) -> 26.059265 | L16: =+(BS!L26-BS!K26) -> 34.37964 | M16: =+(BS!M26-BS!L26) -> 37.801939 | N16: =+(BS!N26-BS!M26) -> 40.11598 | O16: =+(BS!O26-BS!N26) -> 44.004407 | ... Q16: =+(BS!Q26-BS!P26) -> 47.976057
B17: CFO | C17: =+FC!C16 -> 12625 | D17: =+FC!D16 -> 11018 | E17: =+FC!E16 -> 11599 | F17: =+FC!F16 -> 6805 | G17: =+FC!G16 -> 7408 | H17: =+SUM(H7:H11) -> 11419.12 | I17: =+SUM(I7:I11) -> 12707.688 | J17: =+SUM(J7:J11) -> 13753.733 | K17: =+SUM(K7:K11) -> 14660.826 | L17: =+SUM(L7:L11) -> 15590.593 | M17: =+SUM(M7:M11) -> 16624.234 | N17: =+SUM(N7:N11) -> 17710.542 | O17: =+SUM(O7:O11) -> 18919.396 | ... Q17: =+SUM(Q7:Q11) -> 21388.889
B19: Cash From Investing (CFI)
B21: CapEx | C21: =+FC!C23 -> -1367 | D21: =+FC!D23 -> -1484 | E21: =+FC!E23 -> -1852 | F21: =+FC!F23 -> -2064 | G21: =+FC!G23 -> -2112 | H21: =+-Drivers!H108*IS!H5 -> -2103.0741 | I21: =+-Drivers!I108*IS!I5 -> -2133.5794 | J21: =+-Drivers!J108*IS!J5 -> -2241.7429 | K21: =+-Drivers!K108*IS!K5 -> -2355.3242 | L21: =+-Drivers!L108*IS!L5 -> -2463.8462 | M21: =+-Drivers!M108*IS!M5 -> -2580.3479 | N21: =+-Drivers!N108*IS!N5 -> -2702.5337 | O21: =+-Drivers!O108*IS!O5 -> -2836.44 | ... Q21: =+-Drivers!Q108*IS!Q5 -> -3107.9602
B22: Acquisitions | C22: =+FC!C29 -> -2586 | D22: =+FC!D29 -> 385 | E22: =+FC!E29 -> 368 | F22: =+FC!F29 -> 3170 | G22: =+FC!G29 -> 3106 | H22: =+Drivers!H59 -> 0 | I22: =+Drivers!I59 -> 0 | J22: =+Drivers!J59 -> 0 | K22: =+Drivers!K59 -> 0 | L22: =+Drivers!L59 -> 0 | M22: =+Drivers!M59 -> 0 | N22: =+Drivers!N59 -> 0 | O22: =+Drivers!O59 -> 0 | ... Q22: =+Drivers!Q59 -> 0
B23: Other | C23: =+FC!C33 -> 1080 | D23: =+FC!D33 -> 261 | E23: =+FC!E33 -> -1939 | F23: =+FC!F33 -> 1378 | G23: =+FC!G33 -> -1074 | H23: =0 -> 0 | I23: =0 -> 0 | J23: =0 -> 0 | K23: =0 -> 0 | L23: =0 -> 0 | M23: =0 -> 0 | N23: =0 -> 0 | O23: =0 -> 0 | ... Q23: =0 -> 0
B24: CFI | C24: =+FC!C35 -> -2765 | D24: =+FC!D35 -> -763 | E24: =+FC!E35 -> -3349 | F24: =+FC!F35 -> 2524 | G24: =+FC!G35 -> -67 | H24: =+SUM(H21:H23) -> -2103.0741 | I24: =+SUM(I21:I23) -> -2133.5794 | J24: =+SUM(J21:J23) -> -2241.7429 | K24: =+SUM(K21:K23) -> -2355.3242 | L24: =+SUM(L21:L23) -> -2463.8462 | M24: =+SUM(M21:M23) -> -2580.3479 | N24: =+SUM(N21:N23) -> -2702.5337 | O24: =+SUM(O21:O23) -> -2836.44 | ... Q24: =+SUM(Q21:Q23) -> -3107.9602
B26: Cash From Financing (CFF)
B28: Dividends Paid | C28: =+FC!C38 -> -7252 | D28: =+FC!D38 -> -7616 | E28: =+FC!E38 -> -7952 | F28: =+FC!F38 -> -8359 | G28: =+FC!G38 -> -8779 | H28: =+-Drivers!H120*IS!H51 -> -7708.8867 | I28: =+-Drivers!I120*IS!I51 -> -8001.3784 | J28: =+-Drivers!J120*IS!J51 -> -8525.0346 | K28: =+-Drivers!K120*IS!K51 -> -8980.054 | L28: =+-Drivers!L120*IS!L51 -> -9580.355 | M28: =+-Drivers!M120*IS!M51 -> -10240.412 | N28: =+-Drivers!N120*IS!N51 -> -10940.875 | O28: =+-Drivers!O120*IS!O51 -> -11709.234 | ... Q28: =+-Drivers!Q120*IS!Q51 -> -13318.18
B29: ΔLTDebt | C29: =+FC!C39 -> 228 | D29: =+FC!D39 -> -958 | E29: =+FC!E39 -> 1857 | F29: =+FC!F39 -> 2528 | G29: =+FC!G39 -> 13 | H29: =+(BS!H31-BS!G31)+(BS!H30-BS!G30)+(BS!H27-BS!G27) -> -2143 | I29: =+(BS!I31-BS!H31)+(BS!I30-BS!H30)+(BS!I27-BS!H27) -> 0 | J29: =+(BS!J31-BS!I31)+(BS!J30-BS!I30)+(BS!J27-BS!I27) -> 0 | K29: =+(BS!K31-BS!J31)+(BS!K30-BS!J30)+(BS!K27-BS!J27) -> 0 | L29: =+(BS!L31-BS!K31)+(BS!L30-BS!K30)+(BS!L27-BS!K27) -> 0 | M29: =+(BS!M31-BS!L31)+(BS!M30-BS!L30)+(BS!M27-BS!L27) -> 0 | N29: =+(BS!N31-BS!M31)+(BS!N30-BS!M30)+(BS!N27-BS!M27) -> 0 | O29: =+(BS!O31-BS!N31)+(BS!O30-BS!N30)+(BS!O27-BS!N27) -> 0 | ... Q29: =+(BS!Q31-BS!P31)+(BS!Q30-BS!P30)+(BS!Q27-BS!P27) -> 0
B30: ΔLease Liabilities | H30: =+(BS!H32-BS!G32) -> 38.450682 | I30: =+(BS!I32-BS!H32) -> 25.535515 | J30: =+(BS!J32-BS!I32) -> 90.541958 | K30: =+(BS!K32-BS!J32) -> 95.077156 | L30: =+(BS!L32-BS!K32) -> 90.842095 | M30: =+(BS!M32-BS!L32) -> 97.521799 | N30: =+(BS!N32-BS!M32) -> 102.27979 | O30: =+(BS!O32-BS!N32) -> 112.0909 | ... Q30: =+(BS!Q32-BS!P32) -> 118.13966
B31: Share Buybacks | C31: =+FC!C40 -> 591 | D31: =+FC!D40 -> -581 | E31: =+FC!E40 -> -1750 | F31: =+FC!F40 -> -1048 | G31: =+FC!G40 -> -433 | H31: =-MAX(0,(H35+H17+H24+H28+H29+H30)-Drivers!$H$141) -> 0 | I31: =-MAX(0,(I35+I17+I24+I28+I29+I30)-Drivers!$H$141) -> -2370.8757 | J31: =-MAX(0,(J35+J17+J24+J28+J29+J30)-Drivers!$H$141) -> -3077.4972 | K31: =-MAX(0,(K35+K17+K24+K28+K29+K30)-Drivers!$H$141) -> -3420.5248 | L31: =-MAX(0,(L35+L17+L24+L28+L29+L30)-Drivers!$H$141) -> -3637.2336 | M31: =-MAX(0,(M35+M17+M24+M28+M29+M30)-Drivers!$H$141) -> -3900.9956 | N31: =-MAX(0,(N35+N17+N24+N28+N29+N30)-Drivers!$H$141) -> -4169.4131 | O31: =-MAX(0,(O35+O17+O24+O28+O29+O30)-Drivers!$H$141) -> -4485.8129 | ... Q31: =-MAX(0,(Q35+Q17+Q24+Q28+Q29+Q30)-Drivers!$H$141) -> -5080.8887
B32: CFF | C32: =+FC!C45 -> -6786 | D32: =+FC!D45 -> -10250 | E32: =+FC!E45 -> -8310 | F32: =+FC!F45 -> -6910 | G32: =+FC!G45 -> -8140 | H32: =+SUM(H28:H31) -> -9813.4361 | I32: =+SUM(I28:I31) -> -10346.719 | J32: =+SUM(J28:J31) -> -11511.99 | K32: =+SUM(K28:K31) -> -12305.502 | L32: =+SUM(L28:L31) -> -13126.746 | M32: =+SUM(M28:M31) -> -14043.886 | N32: =+SUM(N28:N31) -> -15008.009 | O32: =+SUM(O28:O31) -> -16082.956 | ... Q32: =+SUM(Q28:Q31) -> -18280.929
B34: Net chage in cash and equivalents | C34: =+C17+C24+C32+FC!C47 -> 2915 | D34: =+D17+D24+D32+FC!D47 -> -200 | E34: =+E17+E24+E32+FC!E47 -> -133 | F34: =+F17+F24+F32+FC!F47 -> 1796 | G34: =+G17+G24+G32+FC!G47 -> -478 | H34: =+H17+H24+H32 -> -497.39015 | I34: =+I17+I24+I32 -> 227.39015 | J34: =+J17+J24+J32 -> 0 | K34: =+K17+K24+K32 -> 0 | L34: =+L17+L24+L32 -> 0 | M34: =+M17+M24+M32 -> 0 | N34: =+N17+N24+N32 -> 0 | O34: =+O17+O24+O32 -> 0 | ... Q34: =+Q17+Q24+Q32 -> 0
B35: Cash and equivalents beginning | C35: =+'Balance Sheet'!C8-C34 -> 6769 | D35: =+C36 -> 9684 | E35: =+D36 -> 9484 | F35: =+E36 -> 9351 | G35: =+F36 -> 11147 | H35: =+'Balance Sheet'!G8 -> 10270 | I35: =+H36 -> 9772.6098 | J35: =+I36 -> 10000 | K35: =+J36 -> 10000 | L35: =+K36 -> 10000 | M35: =+L36 -> 10000 | N35: =+M36 -> 10000 | O35: =+N36 -> 10000 | P35: =+O36 -> 10000 | Q35: =+P36 -> 10000
B36: Cash and equivalents end | C36: =+C35+C34 -> 9684 | D36: =+D35+D34 -> 9484 | E36: =+E35+E34 -> 9351 | F36: =+F35+F34 -> 11147 | G36: =+G35+G34 -> 10669 | H36: =+H35+H34 -> 9772.6098 | I36: =+I35+I34 -> 10000 | J36: =+J35+J34 -> 10000 | ... Q36: =+Q35+Q34 -> 10000
B38: Free Cash Flow | C38: =+C17+C24 -> 9860 | D38: =+D17+D24 -> 10255 | E38: =+E17+E24 -> 8250 | F38: =+F17+F24 -> 9329 | G38: =+G17+G24 -> 7341 | H38: =+H17+H24 -> 9316.0459 | I38: =+I17+I24 -> 10574.109 | J38: =+J17+J24 -> 11511.99 | ... Q38: =+Q17+Q24 -> 18280.929
B39: FCF Margin % | C39: =+C38/IS!C5 -> 0.25505717 | D39: =+D38/IS!D5 -> 0.23823352 | E39: =+E38/IS!E5 -> 0.18019395 | F39: =+F38/IS!F5 -> 0.1989253 | G39: =+G38/IS!G5 -> 0.15274021 | H39: =+H38/IS!H5 -> 0.18960032 | I39: =+I38/IS!I5 -> 0.2121275 | J39: =+J38/IS!J5 -> 0.21979946 | ... Q39: =+Q38/IS!Q5 -> 0.2517589

Sheet BS
C1: 2021 | D1: 2022 | E1: 2023 | F1: 2024 | G1: 2025 | H1: 2026 | I1: 2027 | J1: 2028 | K1: 2029 | L1: 2030 | M1: 2031 | N1: 2032 | O1: 2033 | P1: 2034 | Q1: 2035
B3: Balance Sheet
B5: Assets
B7: Cash & Equivalents | C7: =+'Balance Sheet'!C8 -> 9684 | D7: =+'Balance Sheet'!D8 -> 9519 | E7: =+'Balance Sheet'!E8 -> 9366 | F7: =+'Balance Sheet'!F8 -> 10828 | G7: =+'Balance Sheet'!G8 -> 10270 | H7: =+CF!H36 -> 9772.6098 | I7: =+CF!I36 -> 10000 | J7: =+CF!J36 -> 10000 | K7: =+CF!K36 -> 10000 | L7: =+CF!L36 -> 10000 | M7: =+CF!M36 -> 10000 | N7: =+CF!N36 -> 10000 | O7: =+CF!O36 -> 10000 | ... Q7: =+CF!Q36 -> 10000
B8: Short term Investments (STI) | C8: =+'Balance Sheet'!C9 -> 2941 | D8: =+'Balance Sheet'!D9 -> 2112 | E8: =+'Balance Sheet'!E9 -> 4297 | F8: =+'Balance Sheet'!F9 -> 3743 | G8: =+'Balance Sheet'!G9 -> 5536 | H8: =+G8 -> 5536 | I8: =+H8 -> 5536 | J8: =+I8 -> 5536 | K8: =+J8 -> 5536 | L8: =+K8 -> 5536 | M8: =+L8 -> 5536 | N8: =+M8 -> 5536 | O8: =+N8 -> 5536 | ... Q8: =+P8 -> 5536
B9: Accounts Receivable (AR) | C9: =+'Balance Sheet'!C10 -> 3512 | D9: =+'Balance Sheet'!D10 -> 3487 | E9: =+'Balance Sheet'!E10 -> 3410 | F9: =+'Balance Sheet'!F10 -> 3569 | G9: =+'Balance Sheet'!G10 -> 3038 | H9: =+Drivers!H78*IS!H5/365 -> 3789.7714 | I9: =+Drivers!I78*IS!I5/365 -> 3844.7424 | J9: =+Drivers!J78*IS!J5/365 -> 4039.6546 | K9: =+Drivers!K78*IS!K5/365 -> 4244.3299 | L9: =+Drivers!L78*IS!L5/365 -> 4439.8882 | M9: =+Drivers!M78*IS!M5/365 -> 4649.8261 | N9: =+Drivers!N78*IS!N5/365 -> 4870.0067 | O9: =+Drivers!O78*IS!O5/365 -> 5111.3079 | ... Q9: =+Drivers!Q78*IS!Q5/365 -> 5600.5914
B10: Inventory | C10: =+'Balance Sheet'!C13 -> 3414 | D10: =+'Balance Sheet'!D13 -> 4233 | E10: =+'Balance Sheet'!E13 -> 4424 | F10: =+'Balance Sheet'!F13 -> 4728 | G10: =+'Balance Sheet'!G13 -> 4425 | H10: =+Drivers!H90*IS!H16/365 -> 4683.128 | I10: =+Drivers!I90*IS!I16/365 -> 4751.0572 | J10: =+Drivers!J90*IS!J16/365 -> 4991.9158 | K10: =+Drivers!K90*IS!K16/365 -> 5244.8388 | L10: =+Drivers!L90*IS!L16/365 -> 5486.4958 | M10: =+Drivers!M90*IS!M16/365 -> 5745.922 | N10: =+Drivers!N90*IS!N16/365 -> 6018.0053 | O10: =+Drivers!O90*IS!O16/365 -> 6316.1881 | ... Q10: =+Drivers!Q90*IS!Q16/365 -> 6920.8096
B11: Other Current Assets | C11: =+'Balance Sheet'!C18 -> 2994 | D11: =+'Balance Sheet'!D18 -> 3240 | E11: =+'Balance Sheet'!E18 -> 5235 | F11: =+'Balance Sheet'!F18 -> 3129 | G11: =+'Balance Sheet'!G18 -> 7775 | H11: =+G11 -> 7775 | I11: =+H11 -> 7775 | J11: =+I11 -> 7775 | K11: =+J11 -> 7775 | L11: =+K11 -> 7775 | M11: =+L11 -> 7775 | N11: =+M11 -> 7775 | O11: =+N11 -> 7775 | ... Q11: =+P11 -> 7775
B12: Total Current Assets | C12: =+SUM(C7:C11) -> 22545 | D12: =+SUM(D7:D11) -> 22591 | E12: =+SUM(E7:E11) -> 26732 | F12: =+SUM(F7:F11) -> 25997 | G12: =+SUM(G7:G11) -> 31044 | H12: =+SUM(H7:H11) -> 31556.509 | I12: =+SUM(I7:I11) -> 31906.8 | J12: =+SUM(J7:J11) -> 32342.57 | ... Q12: =+SUM(Q7:Q11) -> 35832.401
B14: Plant, Property & Equipement | C14: =+'Balance Sheet'!C24 -> 11338 | D14: =+'Balance Sheet'!D24 -> 11247 | E14: =+'Balance Sheet'!E24 -> 10564 | F14: =+'Balance Sheet'!F24 -> 11485 | G14: =+'Balance Sheet'!G24 -> 11310 | H14: =+G14+CF!H21*-1-IS!H24 -> 12270.873 | I14: =+H14+CF!I21*-1-IS!I24 -> 13157.852 | J14: =+I14+CF!J21*-1-IS!J24 -> 14085.567 | K14: =+J14+CF!K21*-1-IS!K24 -> 14876.339 | L14: =+K14+CF!L21*-1-IS!L24 -> 15684.358 | M14: =+L14+CF!M21*-1-IS!M24 -> 16530.584 | N14: =+M14+CF!N21*-1-IS!N24 -> 17416.881 | O14: =+N14+CF!O21*-1-IS!O24 -> 18347.093 | ... Q14: =+P14+CF!Q21*-1-IS!Q24 -> 20339.322
B15: Goodwill & Intangibles | C15: =+'Balance Sheet'!C30+'Balance Sheet'!C31 -> 53976 | D15: =+'Balance Sheet'!D30+'Balance Sheet'!D31 -> 52413 | E15: =+'Balance Sheet'!E30+'Balance Sheet'!E31 -> 51581 | F15: =+'Balance Sheet'!F30+'Balance Sheet'!F31 -> 49579 | G15: =+'Balance Sheet'!G30+'Balance Sheet'!G31 -> 43513 | H15: =+G15-CF!H22 -> 43513 | I15: =+H15-CF!I22 -> 43513 | J15: =+I15-CF!J22 -> 43513 | K15: =+J15-CF!K22 -> 43513 | L15: =+K15-CF!L22 -> 43513 | M15: =+L15-CF!M22 -> 43513 | N15: =+M15-CF!N22 -> 43513 | O15: =+N15-CF!O22 -> 43513 | ... Q15: =+P15-CF!Q22 -> 43513
B16: Other LT assets | C16: =+'Balance Sheet'!C39-C12-C14-C15 -> 6495 | D16: =+'Balance Sheet'!D39-D12-D14-D15 -> 6512 | E16: =+'Balance Sheet'!E39-E12-E14-E15 -> 8826 | F16: =+'Balance Sheet'!F39-F12-F14-F15 -> 13488 | G16: =+'Balance Sheet'!G39-G12-G14-G15 -> 18949 | H16: =+G16 -> 18949 | I16: =+H16 -> 18949 | J16: =+I16 -> 18949 | K16: =+J16 -> 18949 | L16: =+K16 -> 18949 | M16: =+L16 -> 18949 | N16: =+M16 -> 18949 | O16: =+N16 -> 18949 | ... Q16: =+P16 -> 18949
B17: Total Non-current Assets | C17: =+SUM(C14:C16) -> 71809 | D17: =+SUM(D14:D16) -> 70172 | E17: =+SUM(E14:E16) -> 70971 | F17: =+SUM(F14:F16) -> 74552 | G17: =+SUM(G14:G16) -> 73772 | H17: =+SUM(H14:H16) -> 74732.873 | I17: =+SUM(I14:I16) -> 75619.852 | J17: =+SUM(J14:J16) -> 76547.567 | ... Q17: =+SUM(Q14:Q16) -> 82801.322
B19: Total Assets | C19: =+C12+C17 -> 94354 | D19: =+D12+D17 -> 92763 | E19: =+E12+E17 -> 97703 | F19: =+F12+F17 -> 100549 | G19: =+G12+G17 -> 104816 | H19: =+H12+H17 -> 106289.38 | I19: =+I12+I17 -> 107526.65 | J19: =+J12+J17 -> 108890.14 | ... Q19: =+Q12+Q17 -> 118633.72
B22: Liabilities
B24: Accounts Payable (AP) | C24: =+'Balance Sheet'!C43 -> 4602 | D24: =+'Balance Sheet'!D43 -> 5307 | E24: =+'Balance Sheet'!E43 -> 5590 | F24: =+'Balance Sheet'!F43 -> 5468 | G24: =+'Balance Sheet'!G43 -> 5649 | H24: =+Drivers!H84*IS!H5 -> 5882.0444 | I24: =+Drivers!I84*IS!I5 -> 5967.3641 | J24: =+Drivers!J84*IS!J5 -> 6269.8842 | K24: =+Drivers!K84*IS!K5 -> 6587.5574 | L24: =+Drivers!L84*IS!L5 -> 6891.0804 | M24: =+Drivers!M84*IS!M5 -> 7216.9217 | N24: =+Drivers!N84*IS!N5 -> 7558.6605 | O24: =+Drivers!O84*IS!O5 -> 7933.1803 | ... Q24: =+Drivers!Q84*IS!Q5 -> 8692.5896
B25: Accruals | C25: =+'Balance Sheet'!C46 -> 9652 | D25: =+'Balance Sheet'!D46 -> 9925 | E25: =+'Balance Sheet'!E46 -> 9243 | F25: =+'Balance Sheet'!F46 -> 15811 | G25: =+'Balance Sheet'!G46 -> 8534 | H25: =+Drivers!H96*IS!H5 -> 8724.5564 | I25: =+Drivers!I96*IS!I5 -> 8851.107 | J25: =+Drivers!J96*IS!J5 -> 9299.8207 | K25: =+Drivers!K96*IS!K5 -> 9771.0103 | L25: =+Drivers!L96*IS!L5 -> 10221.211 | M25: =+Drivers!M96*IS!M5 -> 10704.516 | N25: =+Drivers!N96*IS!N5 -> 11211.401 | O25: =+Drivers!O96*IS!O5 -> 11766.909 | ... Q25: =+Drivers!Q96*IS!Q5 -> 12893.304
B26: Taxes Payable | C26: =+'Balance Sheet'!C44 -> 686 | D26: =+'Balance Sheet'!D44 -> 1203 | E26: =+'Balance Sheet'!E44 -> 1569 | F26: =+'Balance Sheet'!F44 -> 1387 | G26: =+'Balance Sheet'!G44 -> 525 | H26: =+Drivers!H102*IS!H43 -> 441.49312 | I26: =+Drivers!I102*IS!I43 -> 458.24432 | J26: =+Drivers!J102*IS!J43 -> 488.23446 | K26: =+Drivers!K102*IS!K43 -> 514.29372 | L26: =+Drivers!L102*IS!L43 -> 548.67336 | M26: =+Drivers!M102*IS!M43 -> 586.4753 | N26: =+Drivers!N102*IS!N43 -> 626.59128 | O26: =+Drivers!O102*IS!O43 -> 670.59569 | ... Q26: =+Drivers!Q102*IS!Q43 -> 762.74111
B27: Short-term debt | C27: =+'Balance Sheet'!C47 -> 4955 | D27: =+'Balance Sheet'!D47 -> 3113 | E27: =+'Balance Sheet'!E47 -> 6878 | F27: =+'Balance Sheet'!F47 -> 2437 | G27: =+'Balance Sheet'!G47 -> 3694 | H27: =+Debt!$C$7 -> 1551 | I27: =+Debt!$C$7 -> 1551 | J27: =+Debt!$C$7 -> 1551 | K27: =+Debt!$C$7 -> 1551 | L27: =+Debt!$C$7 -> 1551 | M27: =+Debt!$C$7 -> 1551 | N27: =+Debt!$C$7 -> 1551 | O27: =+Debt!$C$7 -> 1551 | ... Q27: =+Debt!$C$7 -> 1551
B28: Total Current Liabilities | C28: =+'Balance Sheet'!C58 -> 19950 | D28: =+'Balance Sheet'!D58 -> 19724 | E28: =+'Balance Sheet'!E58 -> 23571 | F28: =+'Balance Sheet'!F58 -> 25249 | G28: =+'Balance Sheet'!G58 -> 21281 | H28: =+SUM(H24:H27)+'Balance Sheet'!$G$53 -> 19478.094 | I28: =+SUM(I24:I27)+'Balance Sheet'!$G$53 -> 19706.715 | J28: =+SUM(J24:J27)+'Balance Sheet'!$G$53 -> 20487.939 | K28: =+SUM(K24:K27)+'Balance Sheet'!$G$53 -> 21302.861 | L28: =+SUM(L24:L27)+'Balance Sheet'!$G$53 -> 22090.965 | M28: =+SUM(M24:M27)+'Balance Sheet'!$G$53 -> 22937.913 | N28: =+SUM(N24:N27)+'Balance Sheet'!$G$53 -> 23826.653 | O28: =+SUM(O24:O27)+'Balance Sheet'!$G$53 -> 24800.685 | ... Q28: =+SUM(Q24:Q27)+'Balance Sheet'!$G$53 -> 26778.635
B30: Current portion LTD | C30: =+'Balance Sheet'!C52 -> 1338 | D30: =+'Balance Sheet'!D52 -> 399 | E30: =+'Balance Sheet'!E52 -> 1960 | F30: =+'Balance Sheet'!F52 -> 648 | G30: =+'Balance Sheet'!G52 -> 1822 | H30: =+Debt!C29 -> 1822 | I30: =+Debt!D29 -> 381 | J30: =+Debt!E29 -> 0 | K30: =+Debt!F29 -> 0 | L30: =+Debt!G29 -> 0 | M30: =+Debt!$G$29 -> 0 | N30: =+Debt!$G$29 -> 0 | O30: =+Debt!$G$29 -> 0 | P30: =+Debt!$G$29 -> 0 | Q30: =+Debt!$G$29 -> 0
B31: Long-term debt | C31: =+'Balance Sheet'!C60 -> 38116 | D31: =+'Balance Sheet'!D60 -> 36377 | E31: =+'Balance Sheet'!E60 -> 35547 | F31: =+'Balance Sheet'!F60 -> 42375 | G31: =+'Balance Sheet'!G60 -> 42119 | H31: =+Debt!C46-H30 -> 42119 | I31: =+Debt!D46-I30 -> 43560 | J31: =+Debt!E46-J30 -> 43941 | K31: =+Debt!F46-K30 -> 43941 | L31: =+Debt!G46-L30 -> 43941 | M31: =+Debt!H46-M30 -> 43941 | N31: =+Debt!I46-N30 -> 43941 | O31: =+Debt!J46-O30 -> 43941 | ... Q31: =+Debt!L46-Q30 -> 43941
B32: Lease liabilities (ST + LT) | C32: =+'Balance Sheet'!C49+'Balance Sheet'!C61 -> 1471 | D32: =+'Balance Sheet'!D49+'Balance Sheet'!D61 -> 1454 | E32: =+'Balance Sheet'!E49+'Balance Sheet'!E61 -> 1362 | F32: =+'Balance Sheet'!F49+'Balance Sheet'!F61 -> 1213 | G32: =+'Balance Sheet'!G49+'Balance Sheet'!G61 -> 1722 | H32: =+Debt!C54 -> 1760.4507 | I32: =+Debt!D54 -> 1785.9862 | J32: =+Debt!E54 -> 1876.5282 | K32: =+Debt!F54 -> 1971.6053 | L32: =+Debt!G54 -> 2062.4474 | M32: =+Debt!H54 -> 2159.9692 | N32: =+Debt!I54 -> 2262.249 | O32: =+Debt!J54 -> 2374.3399 | ... Q32: =+Debt!L54 -> 2601.6252
B33: Other LT liabilities | C33: =+'Balance Sheet'!C72-C28-C30-C31-C32 -> 8619 | D33: =+'Balance Sheet'!D72-D28-D30-D31-D32 -> 8983 | E33: =+'Balance Sheet'!E72-E28-E30-E31-E32 -> 7783 | F33: =+'Balance Sheet'!F72-F28-F30-F31-F32 -> 4692 | G33: =+'Balance Sheet'!G72-G28-G30-G31-G32 -> 3597 | H33: =+G33+CF!H10 -> 3737.5888 | I33: =+H33+CF!I10 -> 3883.5118 | J33: =+I33+CF!J10 -> 4038.9848 | K33: =+J33+CF!K10 -> 4202.7562 | L33: =+K33+CF!L10 -> 4377.4753 | M33: =+L33+CF!M10 -> 4564.2321 | N33: =+M33+CF!N10 -> 4763.7634 | O33: =+N33+CF!O10 -> 4977.3075 | ... Q33: =+P33+CF!Q10 -> 5447.8035
B34: Total Non-current Liabilities | C34: =+'Balance Sheet'!C71 -> 49544 | D34: =+'Balance Sheet'!D71 -> 47213 | E34: =+'Balance Sheet'!E71 -> 46652 | F34: =+'Balance Sheet'!F71 -> 48928 | G34: =+'Balance Sheet'!G71 -> 49260 | H34: =+SUM(H30:H33) -> 49439.039 | I34: =+SUM(I30:I33) -> 49610.498 | J34: =+SUM(J30:J33) -> 49856.513 | K34: =+SUM(K30:K33) -> 50115.361 | L34: =+SUM(L30:L33) -> 50380.923 | M34: =+SUM(M30:M33) -> 50665.201 | N34: =+SUM(N30:N33) -> 50967.012 | O34: =+SUM(O30:O33) -> 51292.647 | ... Q34: =+SUM(Q30:Q33) -> 51990.429
B36: Total Liabilities | C36: =+'Balance Sheet'!C72 -> 69494 | D36: =+'Balance Sheet'!D72 -> 66937 | E36: =+'Balance Sheet'!E72 -> 70223 | F36: =+'Balance Sheet'!F72 -> 74177 | G36: =+'Balance Sheet'!G72 -> 70541 | H36: =+H28+H34 -> 68917.133 | I36: =+I28+I34 -> 69317.213 | J36: =+J28+J34 -> 70344.452 | K36: =+K28+K34 -> 71418.223 | L36: =+L28+L34 -> 72471.888 | M36: =+M28+M34 -> 73603.115 | N36: =+N28+N34 -> 74793.665 | O36: =+O28+O34 -> 76093.332 | ... Q36: =+Q28+Q34 -> 78769.064
B38: Equity
B40: Common stock + APIC | C40: =+'Balance Sheet'!C74 -> 19876 | D40: =+'Balance Sheet'!D74 -> 20582 | E40: =+'Balance Sheet'!E74 -> 20969 | F40: =+'Balance Sheet'!F74 -> 21561 | G40: =+'Balance Sheet'!G74 -> 22341 | H40: =+G40+CF!H9 -> 22626.824 | I40: =+H40+CF!I9 -> 22916.793 | J40: =+I40+CF!J9 -> 23221.463 | K40: =+J40+CF!K9 -> 23541.569 | L40: =+K40+CF!L9 -> 23876.425 | M40: =+L40+CF!M9 -> 24227.113 | N40: =+M40+CF!N9 -> 24594.408 | O40: =+N40+CF!O9 -> 24979.902 | ... Q40: =+P40+CF!Q9 -> 25805.511
B41: Treasury Stock | C41: =+-'Balance Sheet'!C77 -> -51641 | D41: =+-'Balance Sheet'!D77 -> -52601 | E41: =+-'Balance Sheet'!E77 -> -54535 | F41: =+-'Balance Sheet'!F77 -> -55916 | G41: =+-'Balance Sheet'!G77 -> -56423 | H41: =+G41-CF!H31*-1 -> -56423 | I41: =+H41-CF!I31*-1 -> -58793.876 | J41: =+I41-CF!J31*-1 -> -61871.373 | K41: =+J41-CF!K31*-1 -> -65291.898 | L41: =+K41-CF!L31*-1 -> -68929.131 | M41: =+L41-CF!M31*-1 -> -72830.127 | N41: =+M41-CF!N31*-1 -> -76999.54 | O41: =+N41-CF!O31*-1 -> -81485.353 | ... Q41: =+P41-CF!Q31*-1 -> -91309.308
B42: Retained Earnings | C42: =+'Balance Sheet'!C78+'Balance Sheet'!C79 -> 54764 | D42: =+'Balance Sheet'!D78+'Balance Sheet'!D79 -> 56124 | E42: =+'Balance Sheet'!E78+'Balance Sheet'!E79 -> 59507 | F42: =+'Balance Sheet'!F78+'Balance Sheet'!F79 -> 59211 | G42: =+'Balance Sheet'!G78+'Balance Sheet'!G79 -> 66251 | H42: =+G42+IS!H51-CF!H28*-1 -> 69062.425 | I42: =+H42+IS!I51-CF!I28*-1 -> 71980.521 | J42: =+I42+IS!J51-CF!J28*-1 -> 75089.595 | K42: =+J42+IS!K51-CF!K28*-1 -> 78364.613 | L42: =+K42+IS!L51-CF!L28*-1 -> 81858.561 | M42: =+L42+IS!M51-CF!M28*-1 -> 85593.231 | N42: =+M42+IS!N51-CF!N28*-1 -> 89583.36 | O42: =+N42+IS!O51-CF!O28*-1 -> 93853.708 | ... Q42: =+P42+IS!Q51-CF!Q28*-1 -> 103262.46
B43: Minority interest | C43: =+'Balance Sheet'!C81 -> 1861 | D43: =+'Balance Sheet'!D81 -> 1721 | E43: =+'Balance Sheet'!E81 -> 1539 | F43: =+'Balance Sheet'!F81 -> 1516 | G43: =+'Balance Sheet'!G81 -> 2106 | H43: =+G43+IS!H49 -> 2106 | I43: =+H43+IS!I49 -> 2106 | J43: =+I43+IS!J49 -> 2106 | K43: =+J43+IS!K49 -> 2106 | L43: =+K43+IS!L49 -> 2106 | M43: =+L43+IS!M49 -> 2106 | N43: =+M43+IS!N49 -> 2106 | O43: =+N43+IS!O49 -> 2106 | ... Q43: =+P43+IS!Q49 -> 2106
B44: Total Equity | C44: =+'Balance Sheet'!C82 -> 24860 | D44: =+'Balance Sheet'!D82 -> 25826 | E44: =+'Balance Sheet'!E82 -> 27480 | F44: =+'Balance Sheet'!F82 -> 26372 | G44: =+'Balance Sheet'!G82 -> 34275 | H44: =+SUM(H40:H43) -> 37372.249 | I44: =+SUM(I40:I43) -> 38209.439 | J44: =+SUM(J40:J43) -> 38545.685 | K44: =+SUM(K40:K43) -> 38720.285 | L44: =+SUM(L40:L43) -> 38911.854 | M44: =+SUM(M40:M43) -> 39096.218 | N44: =+SUM(N40:N43) -> 39284.228 | O44: =+SUM(O40:O43) -> 39454.257 | ... Q44: =+SUM(Q40:Q43) -> 39864.659
B46: Total Liabilities + Equity | C46: =+C36+C44 -> 94354 | D46: =+D36+D44 -> 92763 | E46: =+E36+E44 -> 97703 | F46: =+F36+F44 -> 100549 | G46: =+G36+G44 -> 104816 | H46: =+H36+H44 -> 106289.38 | I46: =+I36+I44 -> 107526.65 | J46: =+J36+J44 -> 108890.14 | ... Q46: =+Q36+Q44 -> 118633.72
B48: BS Check | C48: =+C19-C46 -> 0 | D48: =+D19-D46 -> 0 | E48: =+E19-E46 -> 0 | F48: =+F19-F46 -> 0 | G48: =+G19-G46 -> 0 | H48: =+H19-H46 -> 0 | I48: =+I19-I46 -> 0 | J48: =+J19-J46 -> 0 | ... Q48: =+Q19-Q46 -> 0

Sheet WACC
B2: WACC | F2: Comparable Companies Unlevered Betas
B3: Capital structure | F3: Company name | G3: TICKER | H3: Levered Beta | I3: Total Debt | J3: Equity | K3: TOTAL (D+E) | L3: D / E | M3: Tax Rate | N3: Unlevered Beta
B4: Total debt | D4: =+Debt!C57*1000000 -> 4.7252451e+10 | F4: KEURIG DR PEPPER INC. (XNAS:KDP) | G4: KDP | H4: 0.3822 | I4: 16141000000 | J4: 47193000000 | K4: =+I4+J4 -> 63334000000 | L4: =+I4/J4 -> 0.34202106 | M4: 0.226 | N4: =+H4*(J4/K4)+$D$21*(I4/K4) -> 0.28479434
B5: Total Equity | D5: 398889317790 | F5: Pepsico, Inc. (XNAS:PEP) | G5: PEP | H5: 0.3298 | I5: 40901000000 | J5: 185019345570 | K5: =+I5+J5 -> 225920345570 | L5: =+I5/J5 -> 0.22106337 | M5: 0.19 | N5: =+H5*(J5/K5)+$D$21*(I5/K5) -> 0.27009245
B6: Debt to Value | D6: =+D4/(D5+D4) -> 0.10591353 | F6: MONSTER BEVERAGE CORPORATION (XNAS:MNST) | G6: MNST | H6: 0.5268 | I6: 0 | J6: 90348379040 | K6: =+I6+J6 -> 90348379040 | L6: =+I6/J6 -> 0 | M6: 0.232 | N6: =+H6*(J6/K6)+$D$21*(I6/K6) -> 0.5268
B7: Equity to Value | D7: =+D5/(D5+D4) -> 0.89408647 | F7: CELSIUS HOLDINGS, INC. (XNAS:CELH) | G7: CELH | H7: 1.0037 | I7: 669926000 | J7: 7203906450 | K7: =+I7+J7 -> 7873832450 | L7: =+I7/J7 -> 0.092994822 | M7: 0.257 | N7: =+H7*(J7/K7)+$D$21*(I7/K7) -> 0.91830261
B8: D/E | D8: =+D4/D5 -> 0.11846006 | F8: NATIONAL BEVERAGE CORP. (XNAS:FIZZ) | G8: FIZZ | H8: 0.8348 | I8: 58936000 | J8: 3384193095 | K8: =+I8+J8 -> 3443129095 | L8: =+I8/J8 -> 0.017415082 | M8: 0.236 | N8: =+H8*(J8/K8)+$D$21*(I8/K8) -> 0.82051074
B9: E/D | D9: =+D5/D4 -> 8.4416641 | F9: Median All | H9: =+MEDIAN(H4:H8) -> 0.5268 | N9: =+MEDIAN(N4:N8) -> 0.5268
F10: Average All | H10: =+AVERAGE(H4:H8) -> 0.61546 | N10: =+AVERAGE(N4:N8) -> 0.56410003
B11: Cost of Equity | F11: Median Restricted | H11: =+MEDIAN(H4:H6) -> 0.3822 | N11: =+MEDIAN(N4:N6) -> 0.28479434
B12: Risk Free Rate | D12: 0.0425 | F12: Average Restricted | H12: =+AVERAGE(H4:H6) -> 0.41293333 | N12: =+AVERAGE(N4:N6) -> 0.36056226
B13: Implied Market Return | D13: =+D14+D12 -> 0.0952
B14: Equity to Risk Premium (ERP) | D14: 0.0527
B15: Company Beta | D15: =+D16*(1+D8)-D21*D8 -> 0.40327449
B16: Assets Beta | D16: =+N12 -> 0.36056226
B17: Cost of equity | D17: =+D12+D15*D14 -> 0.063752566
B19: Cost of Debt
B20: Corporate Marginal Tax Rate | D20: 0.21
B21: Debt Beta | D21: =+MAX((D22-D12)/(D13-D12),0) -> 0
B22: Interest expense % over debt | D22: =+Debt!C58/Debt!C57 -> 0.033388744
B23: After tax cost of debt | D23: =+D22*(1-D20) -> 0.026377108
B25: WACC | D25: =+D17*D7+D23*D6 -> 0.059793999
B26: Damodaran WACC | D26: 0.0589
B28: #VALUE! | D28: {=+_FV(B28,"Beta")} -> 0.2869

Sheet DCF + DDM
C2: 2021 | D2: 2022 | E2: 2023 | F2: 2024 | G2: 2025 | H2: 2026 | I2: 2027 | J2: 2028 | K2: 2029 | L2: 2030 | M2: 2031 | N2: 2032 | O2: 2033 | P2: 2034 | Q2: 2035
B3: EBIT | C3: =+IS!C27 -> 11109 | D3: =+IS!D27 -> 12600 | E3: =+IS!E27 -> 13336 | F3: =+IS!F27 -> 10647 | G3: =+IS!G27 -> 14315 | H3: =+IS!H27 -> 13944.62 | I3: =+IS!I27 -> 14463.399 | J3: =+IS!J27 -> 15330.194 | ... Q3: =+IS!Q27 -> 23394.528
B4: =+Drivers!B54 -> Mergers and Acquisitions | C4: =+Drivers!C54*-1 -> 1173 | D4: =+Drivers!D54*-1 -> -408 | E4: =+Drivers!E54*-1 -> -836 | F4: =+Drivers!F54*-1 -> -1377 | G4: =+Drivers!G54*-1 -> 654 | H4: =-Drivers!H58 -> -158.8 | I4: =-Drivers!I58 -> -158.8 | J4: =-Drivers!J58 -> -158.8 | K4: =-Drivers!K58 -> -158.8 | L4: =-Drivers!L58 -> -158.8 | M4: =-Drivers!M58 -> -158.8 | N4: =-Drivers!N58 -> -158.8 | O4: =-Drivers!O58 -> -158.8 | ... Q4: =-Drivers!Q58 -> -158.8
B5: =+Drivers!B61 -> Restructuring | C5: =+Drivers!C61*-1 -> -378 | D5: =+Drivers!D61*-1 -> -117 | E5: =+Drivers!E61*-1 -> -191 | F5: =+Drivers!F61*-1 -> -133 | G5: =+Drivers!G61*-1 -> -97 | H5: =+Drivers!H61*-1 -> -134.5 | I5: =+Drivers!I61*-1 -> -134.5 | J5: =+Drivers!J61*-1 -> -134.5 | ... Q5: =+Drivers!Q61*-1 -> -134.5
B6: NOPAT | C6: =+SUM(C3:C5)*(1-WACC!$D$20) -> 9404.16 | D6: =+SUM(D3:D5)*(1-WACC!$D$20) -> 9539.25 | E6: =+SUM(E3:E5)*(1-WACC!$D$20) -> 9724.11 | F6: =+SUM(F3:F5)*(1-WACC!$D$20) -> 7218.23 | G6: =+SUM(G3:G5)*(1-WACC!$D$20) -> 11748.88 | H6: =+SUM(H3:H5)*(1-WACC!$D$20) -> 10784.542 | I6: =+SUM(I3:I5)*(1-WACC!$D$20) -> 11194.378 | J6: =+SUM(J3:J5)*(1-WACC!$D$20) -> 11879.146 | ... Q6: =+SUM(Q3:Q5)*(1-WACC!$D$20) -> 18249.97
B7: =+IS!B24 -> Depreciation & Amortization | H7: =+IS!H24 -> 1142.2015 | I7: =+IS!I24 -> 1246.5997 | J7: =+IS!J24 -> 1314.0287 | K7: =+IS!K24 -> 1564.5518 | L7: =+IS!L24 -> 1655.8269 | M7: =+IS!M24 -> 1734.1218 | N7: =+IS!N24 -> 1816.2367 | O7: =+IS!O24 -> 1906.2284 | ... Q7: =+IS!Q24 -> 2088.7035
B8: =+CF!B21 -> CapEx | C8: =+CF!C21 -> -1367 | D8: =+CF!D21 -> -1484 | E8: =+CF!E21 -> -1852 | F8: =+CF!F21 -> -2064 | G8: =+CF!G21 -> -2112 | H8: =+CF!H21 -> -2103.0741 | I8: =+CF!I21 -> -2133.5794 | ... Q8: =+CF!Q21 -> -3107.9602
